Workbook

Sheet ステージ
A1: NO | B1: レベル | D1: 場所 | F1: 報酬 | H1: タグ
A2: {=_xlfn.SEQUENCE(324)} -> 1 | B2: =エリア内容!A4 -> ★4混沌 | D2: =エリア内容!B4 -> ルノヴァ旧市街
A3: 2 | B3: =エリア内容!A5 -> ★3都市 | D3: =エリア内容!B5 -> エラミア区
A4: 3 | B4: =エリア内容!A6 -> ★3大学校 | D4: =エリア内容!B6 -> エルメナ大学
A5: 4 | B5: =エリア内容!A7 -> ★3貧困 | D5: =エリア内容!B7 -> ゴンサル地区
A6: 5 | B6: =エリア内容!A8 -> ★3大樹 | D6: =エリア内容!B8 -> 大樹リラン駐屯地
A7: 6 | B7: =エリア内容!A9 -> ★2高級都市 | D7: =エリア内容!B9 -> フェリス庭区
A8: 7 | B8: =エリア内容!A10 -> ★2夜学校 | D8: =エリア内容!B10 -> ネリクス魔法学校
A9: 8 | B9: =エリア内容!A11 -> ★2行政区 | D9: =エリア内容!B11 -> ザイカ行政区
A10: 9 | B10: =エリア内容!A12 -> ★1街A | D10: =エリア内容!B12 -> ミルネ街
A11: 10 | B11: =エリア内容!A13 -> ★1街B | D11: =エリア内容!B13 -> コロッタ街
A12: 11 | B12: =エリア内容!A14 -> ★1洞窟 | D12: =エリア内容!B14 -> イリユ洞窟
A13: 12
A14: 13
A15: 14
A16: 15
A17: 16
A18: 17
A19: 18
A20: 19
A21: 20
A22: 21
A23: 22
A24: 23
... A325: 324

Sheet エリア内容
A1: エリアごとのシナリオ | D1: → | E1: シナリオルート!A1
A3: レベル | B3: 場所 | D3: 概要
A4: ★4混沌 | B4: ルノヴァ旧市街 | D4: 過去に栄えていた街。リラン大樹を人間の手で管理しようとしたところバクが大減少し悪夢が蔓延したことで崩壊した。浄化することが出来ず放置されている
A5: ★3都市 | B5: エラミア区 | D5: 一般的な人間と妖精が働く場所のひとつ。働き三昧で疲弊した人が多い。ブラック企業も多くあり悪夢を見る人が多い。
A6: ★3大学校 | B6: エルメナ大学 | D6: ネリクス魔法学校から一部の人が進学する学校。研究で疲弊した人や密かに暮らしている人が悪夢を見る。
A7: ★3貧困 | B7: ゴンサル地区 | D7: 様々な理由で落ちぶれた人間と妖精が住む場所。辛い生活をしている人が多くトラウマから悪夢を見る人が多い。あまりの辛さに奮闘する人が多く一部の人は直ぐに再奮闘する
A8: ★3大樹 | B8: 大樹リラン駐屯地 | D8: 妖精が生まれるために必要な木の実を生む大樹。数十名の妖精が住んでいる。ルノヴァ旧市街から出てくる悪夢から大樹を守っているが、たまにミスって酷い悪夢を夢に見る。
A9: ★2高級都市 | B9: フェリス庭区 | D9: 超富裕層の人間と妖精が住む小さくも豪華な都市。大手企業の社長が多く存在していて何もしなくてもお金が入ってくる人もいる。自分の会社がつぶれないかたまに不安になる
A10: ★2夜学校 | B10: ネリクス魔法学校 | D10: 魔法を勉強できる学校。一般の人間と妖精が学びに来ている。魔法や基礎勉強など、生きる上で必要な知識を学べる。先生たちが徹夜していて作業が終わらない悪夢を見ることがある。
A11: ★2行政区 | B11: ザイカ行政区 | D11: 政治を担う人間と妖精が住む場所。大金持ちの骨太なものたちが住む。政治を担っているが、良くも悪くも一般市民に文句を言われる政治をする。
A12: ★1街A | B12: ミルネ街 | D12: 普通の人間と妖精が住む街。妖精文化がわずかに強く、植林が多く魔法系の会社が多い。
A13: ★1街B | B13: コロッタ街 | D13: 普通の人間と妖精が住む街。人間文化がわずかに強く、ノスタルジックな工業系の会社が多い。
A14: ★1洞窟 | B14: イリユ洞窟 | D14: バクが住む洞窟。大樹リランの根の下にある。悪夢を食べたバクが分泌する巣をつくる成分と大樹リランの実が地面にしみこませたエキスが反応を起こして妖精になるエネルギーが出来る。
A18: `以下の文章はメモである`イリユ洞窟で形成されるエネルギーは無意識的に自分の居場所を選び、そのあとに妖精が誕生する。一度人の手によって滅ぼされかけたが人の手で管理しようとすると直ぐに消滅するほど神聖な存在のため管理をあきらめられた。人と妖精の悪夢を多く食べて生きている。

Sheet シナリオルート
A1: エリアの大まかな設定 | D1: → | E1: エリア内容!A1 | H1: プレイヤー名 | J1: ティーナ | L1: 幼馴染名 | M1: ラーラ
A3: 場所 | B3: 概要 | G3: ステージの方向性 | L3: フェーズ1 | Q3: フェーズ2 | V3: フェーズ3 | AA3: ルート
A4: =エリア内容!B4 -> ルノヴァ旧市街 | B4: 過去にここで死したものの悪夢が出てくる。 ひどく残酷で見るに堪えないもの。 政府がバクを管理しようとしたが繊細な生き物だったため個体数が大幅に減り、そのせいで悪夢が増えすぎて壊滅してしまった土地。昔はここに人や妖精が住んでいたが、一連の出来事によってほかの場所へ移住したことを明かす。 | G4: 特殊な戦い方をする敵が多い。 | L4: 赤いクロワッサン | Q4: 熱されたかき氷 | V4: 上を向いたオジギソウ
A14: =エリア内容!B5 -> エラミア区 | B14: 一般的な人間と妖精が働く場所。 仕事関連の悪夢が出てくる。 頑張ったものが全部台無しになったり、リセットされたりなど。仕事のトラウマはあんまわかんないなぁ。 高級都市で暮らしている存在に首をつかまれている苦しさを見せる。 | G14: 何かしらの行動を起因として戦況を一気に変える行動を起こしてくる敵が多い。 偶数時になるたびに受けたダメージを攻撃力に変換する敵 悪夢が多いほど強くなる敵 一定量の攻撃力を食らうとダメージを軽減する敵 | L14: 納品に追われる悪夢 エラミア区の状況を説明する。高級都市よりも悪辣な環境で夜なのに明るい場所も多い。そのなかでも一人の人間がうなされているのを見つける。 | Q14: みんなでやれば怖くない悪夢 前の場所よりもひどく、大勢の人と妖精が働いている場所を見つける。寝ているものもちらほらいて、夜なのに騒がしい。 | V14: 感覚麻痺の悪夢 あまりにも働きすぎて感覚がマヒしてしまった悪夢にかかっている、精神が限界突破している妖精を見つける。行き過ぎた労働は生命を殺してしまう
A24: =エリア内容!B6 -> エルメナ大学 | B24: 研究をしていたりバイト詰めの人や妖精がいる場所。 研究や単位の悪夢が出てくる。じわじわとやってくる就活におびえている人間、人間に恋に落ちたが人間の女思い人を取られそうな妖精など。 一定周期でやってくる強力な攻撃に対策する力を求められる。 | G24: 一定時間が経過するごとに何かしらの行動を起こす敵が多い。 1時間経過するたびに攻撃された回数分回復する敵 1時間経過するたびに強力な攻撃をする敵 3時になると超強力な攻撃を1回行い消滅する敵 | L24: 最高の大学生活をしようといろんな人にアプローチをするが誰にも目を向けられない悪夢。 何度も倒れてもあきらめずに立ち直る姿は勇敢だが、苦痛にもなる。 | Q24: 眠気に襲われる悪夢 大学で研究をしている人が多いことを説明。講義で眠気に襲われかけて怒られる悪夢を見ている人を見つける。横には大量の白紙レポートがあり、書かなければいけない。 | V24: 最終締め切りに襲われる悪夢 これを落としたら落第レベルの研究論文の提出に追われる。どんな方法でもよいのでこれを解決しなければならない。
A34: =エリア内容!B7 -> ゴンサル地区 | B34: 様々な理由で落ちぶれた浮浪者がさまよう町。 過去のトラウマを思い出して悪夢を見る。 中には昔のルノヴァ旧市街を知る老人もいる。 攻撃力の低い大量の攻撃に耐える力が試される。 | G34: 寄生型悪夢を持っている敵が多い 消化されると2回分裂する低級寄生型悪夢を生成する敵 消化されると最大被弾ダメージ分の攻撃力を持つ中級寄生型悪夢を生成する敵 消化されると消化ダメージを20%軽減する上級寄生型悪夢を生成する敵 | L34: 資産を奪う悪夢 多くの資産を持っていたのに、ほかの競合他社に目をつけられて倒産まで追い込まれた。何度逃げようとしても詰め寄られ、資産（HP）を削られる。 | Q34: 薬に染まる悪夢 一度大きなお金を渡せばそれ以下の金銭では購入できなくなる。報酬を得るために強い刺激を与えると、最終的にそれは自分の命を削ることになる。 | V34: 多くの叱責を受ける悪夢 世の中の人々におおくの悪口をかけられて精神が病んでしまった。自分に自信を無くし、いつか他人からの悪口に対してダメージを受けなくなってしまった。
A44: =エリア内容!B8 -> 大樹リラン駐屯地 | B44: 妖精が生まれる成分を守る場所。 大樹の周りに存在する防衛拠点。 ルノヴァ旧市街から来る悪夢の存在を伝える。 大樹に成る木の実が、妖精が生まれるために必要なものであると伝える。 熟れて落ちた木の実がバクの巣まで染み込み、そこにある成分とくっついて妖精が生まれると伝える。 どれだけ倒しても終わらない悪夢を倒しきる力を求められる。 | G44: 敵は少ないが倒すのが難しい敵が多い 同時に消化されたものが存在しない場合復活する敵 消化ダメージを受けるほどHPが上昇する敵 消化ダメージを受けると経過時刻を追加で1回進行する敵 | L44: 妖精が生まれない悪夢 かつての大厄災、バクが減ったことで妖精の繁殖も激減してしまった時期があった。どうして誰もいないの。どうして私だけなの。悲しみに暮れる妖精は悲鳴を上げ、ともに朽ち果てるまで何度でもよみがえる。 | Q44: 悪夢が倒せない悪夢 悪夢が悪夢を呼び、無限に膨れ上がる。 倒しても倒しきれない。一人、また一人と悪夢に呑まれていく光景を見てまた悪夢が生まれる。 このループを終わらせて。すべての悪夢を食べつくして | V44: 妖精が殺される悪夢 人間が絶対に裏切らないとは断言できない。 行政区の人間は虎視眈々と妖精の自由を奪える日を狙っているかもしれない。知らぬ間に私たちに何かを加え、知らぬ間に自我を失っていった。
A54: =エリア内容!B9 -> フェリス庭区 | B54: 事業に成功した人間や妖精だけが住む街。 白と緑が特徴的なきれいな場所。 事業に成功した社長の人間や妖精たちがお金をいっぱい使って暮らしている。 豊かな暮らしをしているせいで悪夢はあんまり見ない。 普通の町との差を見せつける。時は金なり的な感じで、時間とステータスが関連する攻撃をしてくる。 | G54: 現在時刻をトリガーとしてアクションを起こす敵が多い 時刻に7が含まれるたびに攻撃力が大幅に上がる敵 時間が経過するたびに攻撃力が変動する敵 5が含まれる時刻のとき受ける消化ダメージ2倍、それ以外は半減する敵 | L54: 宝くじを外す悪夢 大量の宝くじを購入して遊戯をする。 当たったらうれしい。外れたら何も思わない。 当たれば当たるほど嬉しくなるよね。 | Q54: すぐにものを捨てられる悪夢 良いものも悪いものもすぐに捨てられる。 なんで、まだ使えるのに、どうして捨てるの。まだ見捨てないで、私はまだあなたと一緒にいたいのに。 | V54: 生活リズムが治らない悪夢 起きるのは夕方、眠るのは朝。 もう何度目だろう。夜は体がよく動くからしょうがない。夜は夜空がきれいで友人たちもにぎわっている。朝に起きなくてもいいんだ。僕はもう成功した大人だから
A64: =エリア内容!B10 -> ネリクス魔法学校 | B64: この世界で生まれた人間と妖精が最初に行く学校。 魔法と一般常識を勉強する場所。 精神が幼稚な人間からある程度成熟するまで幅広い人物が存在する。 ほかの人物と見比べて背伸びをするような悪夢が存在する。倒す順番をよく考える必要がある。 | G64: ほかの悪夢や種を監視してアクションを起こす敵が多い。普通にやっても倒せず、自滅を待つものが多い。 他の悪夢の攻撃力が自身より高かったらHPが増える敵 他の悪夢より受けたダメージが多いたびに攻撃力が上がる敵 胃袋内の他の悪夢をすべて倒し、その悪夢のステータスを追加で獲得する敵 | L64: ほかの存在を敵視する悪夢 友人はいらない。みんな敵だ。友好心はいらない。みんな敵だから。実力と根性があればどうとでもなる。だから何も考えずにほかの人を傷つけて、踏み越えればいい。 | Q64: 疑心暗鬼になる悪夢 なんで私だけひどく当たるの。みんな仲良くしてるのに、私が話してる時だけちょっと気まずい気がする。みんな私だけを仲間はずれにしようとしているの？おはようの声も、私にだけ小さい気がする。ご飯の量も、ちょっと少ない気がする。みんなそうやって私を馬鹿にするなら、仕返しをすればいいんだ。 | V64: 自己中心になる悪夢 自分よりすごい人がいなくなれば自分が大学校に進学できる。ほかの生徒を支配して自分の配下に置けばいい。かわりに僕が君たちの代わりに動くから、全部私にゆだねてほしい。
A74: =エリア内容!B11 -> ザイカ行政区 | B74: この世界を動かしている政府がいる場所。 人間が多く存在する。過去に一度妖精の誕生を管理しようと試みてバクの洞窟でバクを管理し、妖精を人口で生育しようとした。結果は大失敗で一度バクと妖精が大減少したことがある。妖精がいなくなれば文明の発達が遅れてしまうので有効活用するほうが効率的であるので妖精をどうにかして人の配下に落そうと試みている。 | G74: 自分の存在する場所を起点としたアクションを行ってくる。特異な地位と不得意な地位が顕著なことが多い。 消化ライン下にいると攻撃力が上がる敵 胃袋の端に隣接しているとHPが上がる敵 3箇所以上消化ラインに触れていると大ダメージを受ける敵 | L74: ほかの権力者に見放される悪夢 他人からの信頼は必要なものであり、たった一人の力は国家には及ばない。金を使ってあがいても、大きな力に滅ぼされるだけ。そうならないように悪夢の中では必死にあがく。 | Q74: 依存する悪夢 妖精が生まれるにはいくつかの手順が必要になる。大樹リランの実った木の実が地面に落ち、土の中に染みたエキスがイリユ洞窟に住むバクが放出する成分と混ざり合うことで妖精の卵が生まれる。30年前、これを知った政府はバクを飼育して生まれる妖精の能力をコントロールしようと試みた。結果は大失敗だった。バクはとても繊細で、人間が管理できるような生物ではなかった。これによりバクと妖精が大激減し、人類は孤独な運命を歩むことになりかけた。 | V74: 妖精に人類を支配される悪夢 妖精は人類よりも大きな能力を秘めている生物である。その存在があったからこそ人類は今の生活を手に入れた。彼らは崇拝すべき存在だが、完全に力を与えてしまえば人類は今の生活ができなくなる。今も大妖精が私たちを管理する秘策を進めているかもしれない。
A84: =エリア内容!B12 -> ミルネ街 | B84: 妖精が多い街。工業と植物が組み合わさったファンタジー寄りの住居が設計されている。妖精がどのように住む場所を決めるのかを知ることができる。政府に対しては少しの不満を持っているが、いざとなれば自分たちのほうが強いと思っている。大樹リランで自分の子孫を守る仕事に就くことに憧れがあるものもいる。 悪夢が蔓延し、バクが消え、人間に羽をちぎられることに恐怖する。 比較的普通な悪夢が多い。ちょぴり強く、大きなパワーで攻撃される。 | G84: バカ力系の攻撃をする敵が多い。 普段は攻撃せず3回時間が経過するたびに500%の攻撃を1回行う敵 通常の攻撃を10個に分散して攻撃する敵 受けたダメージを味方に分散する敵 | L84: すぐにものを壊す悪夢 人間が作るものは脆い。 成長期は力のコントロールができずにいろんなものを壊しがち。間違えて大切なものを壊してしまう悪夢。ああ、もう同じものは手に入らないのに | Q84: 人間を壊す悪夢 少しだけ力の使い方を覚えた時期に訪れる悪夢。力を弱めればいいと気づくが、分散しても結局壊してしまう。力の使い方を理解したと勘違いするこの時期が一番恐ろしい。この時期は人間と触れ合うのは禁止されているのに、自分の制御を過信して人間と出会う。結果はみんな同じ。全身が血まみれになり、絶叫し、泣き叫ぶ。あなたが悪いの。あなたが信じたのが悪い。もっと自分を理解していればよかったのに。最初から最後まで全部あなたのせいだよ | V84: 精神が乱れた悪夢 成長期を終えた妖精のほとんどは力の使い方や魔法の出し方を完全に学び、自分の好きな人生を歩み始める。大学校に通ってもいいし、エラミア区で仕事に励んでもいい。力の使い方を間違えたらいけない。暴君になってほかの人間や妖精を支配下に置いてはいけない。自分が傷つかなければいいなんてことはないんだよ。
A94: =エリア内容!B13 -> コロッタ街 | B94: 人間が多い街。工業メインの街並みをしている。いつか妖精と結婚したいと思ってる特殊性癖の人間とか、働きたがらない人間がいる。ここも比較的普通。 政府のことはぐちぐちいうけど、なんだかんだどうでもいいと思っている。昔、旧市街に住んでいて子供を亡くした人間もいることを伝える。 政府に親を殺された悪夢とかよりも休みより平日が多いことに対する悪夢や、人生が短すぎることを嫌がる悪夢がいる。 | G94: 様々な方向に少しだけ強い敵が多い 胃の中で10回時間が経過した後攻撃を1回行い消化される敵 ほかの悪夢が消化されるたびにHPと攻撃力があがる敵 消化されると時刻を3時にする敵 | L94: 休日が週１になる悪夢 政府が平日を１日増やすと言った。 休日は週に１回だけ。 毎日仕事をするたびに鬱憤がたまっていく。 政府は悪だ。市民のことを何も考えてない！ 誰もがそう思い、やがてザイカ行政区の前にでもが生まれる。私はその中に混じりたまった鬱憤を吐き続けた。 | Q94: 妖精と結婚できない悪夢 たまにコロッタ街へ訪れる一匹の妖精に見惚れた。 どんなことにも協力的で、真剣で、心の感情を大事にする妖精だった。だけど、ぱたりと姿を見せなくなり、いやな想像が頭をよぎり、夢の中にも現れる。 周りにいる人と妖精がどんどん愛をはぐくみ始めて私は焦る。歩くたびに年を取り、孤独なまま体だけが大人になっていった。 | V94: おなかが痛くなる悪夢 朝に賞味期限が切れたご飯を食べた。少し時間がたつとおなかが痛くなって何度もトイレにこもっていた。 神様に何度も祈って祈って、祈り続ける。それでもおさまらず、いつの間にか夜になっていた。
A104: =エリア内容!B14 -> イリユ洞窟 | B104: バクが住んでいる場所。バクが悪夢を食べることで生み出す夢の種が多く成長している。夢の種からあふれる花粉と大樹リランから落ちた木の実から染み出る成分が融合して妖精が生まれる。バクにも学校があり、そこで生きるすべを教えてもらえる。同級生もいる。最初はバクの形だけど、成長すると人間の姿になる。これは食べている悪夢と、妖精の元を大量に摂取する環境に適応するためにはこのほうがよかったため。原初の悪夢が多く、難易度が高い。本来は悪夢を見ないバクだが、深淵に潜るとかつての大量絶滅のころの悪夢が潜んでいる。 | G104: 敵味方問わず接触することで何かしらのアクションを起こす敵が多い。 接している夢の種を自分が消化されるまでその場に残す敵 接している悪夢の攻撃力を5倍、HPを半分にする敵 受けた攻撃力の10%を自身の攻撃力に加算する敵 | L104: 人間化できない悪夢 ほかのバクが成長できているのに自分だけ成長できない悪夢。バクは両性のバクが愛に落ちることで生まれた卵から孵る。生まれたときは動物のバクのような姿をしているが、親が与える悪夢の性質と本人の持つ自我によって人間の姿に変化していく。変態期を迎えると通常の個体は人間の姿に変わり、基本的にその姿で一生を遂げる。 | Q104: バクを失う悪夢 バク同士にも友好関係や恋愛感情が存在する。夢の花は悪夢を取り込むことで生まれる副産物で、生える花はバク自身と食べた悪夢の相性によって決まる。花は妖精を生むためのエネルギーになる大変貴重な存在だ。バクは他のバクが生やした花の香りからバクが近くにいるか識別することができる。これには欠陥があり、幼ければ幼いほど花をバクだと勘違いしやすい。 | V104: 人間に支配される悪夢 人間が持つ技術が発展し、バクが完全に家畜となった悪夢。いずれありうる世界線。

Sheet タスク(イラスト)
A2: 内容 | E2: 必要度 | G2: 概要
A3: マップの細かな描画 | E3: 遅くても欲しい
A4: 報酬に表示する夢の花アイコン*n | E4: 早めにほしい
A5: ゲーム内のバク立ち絵 | E5: できたら欲しい
A6: 悪夢の見た目*n | E6: 早めにほしい
A7: ボタンの見た目 | E7: できたら欲しい
A8: タイトルの女の子 | E8: 完了
A9: 設定画面 | E9: 遅くても欲しい
A10: オープニングスチル | E10: 遅くても欲しい
A11: エンディングスチル*n | E11: 遅くても欲しい
A12: 夢の花胃の中のブロック | E12: 早めにほしい
A13: 4日ごとの魔法学校挿絵 | E13: 早めにほしい
A14: 突発イベント別キャラ挿絵 | E14: 遅くても欲しい
E15: 完了
E16: 完了
E17: 完了
E18: 完了
E19: 完了
E20: 完了
E21: 完了
E22: 完了
E23: 完了
E24: 完了
E25: 完了
E26: 完了
... E339: 完了

Sheet 戦闘仕様
A2: プレイヤー
B3: 胃袋耐久値 | E3: 胃袋が消化不良を起こすまでの耐えられる耐久力。0になると消化間隔*2の時間を使い10%回復する。
B4: 消化ダメージ | E4: 消化が進行した際に与えるダメージ量
B5: 消化間隔 | E5: 消化が進行するスピード
B6: 時刻 | E6: 22時から始まり6時になると試合終了
B7: 悪夢ダメージ | E7: 消化が進行する際に悪夢から受けるダメージ
B8: 悪夢耐久値 | E8: 悪夢が持っている消化値

Sheet タスク(実装)
A2: 内容 | E2: 必要度 | G2: 概要
A3: 各エリアのシナリオ | E3: 早めにほしい
A4: 各エリアのエンディング | E4: 遅くても欲しい
A5: 花のバリエーション | E5: 早めにほしい
A6: エリアごとの花の割りあて | E6: 早めにほしい
A7: エリアごとの悪夢の割り当て | E7: 早めにほしい
A8: 悪夢のバリエーション | E8: 早めにほしい
A9: 4日に１回シナリオを挟む | E9: 早めにほしい
A10: 消化完了シーンのボタン配置改善(重なる) | E10: 遅くても欲しい
A11: 悪夢と花の効果実装 | E11: 早めにほしい

Sheet 選択肢
B2: 完了
B3: 早めにほしい
B4: 遅くても欲しい
B5: できたら欲しい

Sheet ステージ設計データ
A1: ステージ設計データ｜9通常ステージ+3強敵ステージ用
A2: 目的：各エリアごとに「汎用悪夢」「特殊悪夢」「強敵悪夢」「汎用夢の種」「特殊夢の種」「高レア夢の種」の必要数と候補IDを整理する。セル幅・行高は変更せず、長文セルは横結合で確保。評価済みの良スコア候補は下の参照表に正確な効果情報を記載。
A5: 設計ルール（数の目安）
A6: 対象 | B6: 通常1-3 | C6: 通常4-6 | D6: 通常7-9 | E6: 強敵1 | F6: 強敵2 | G6: 強敵3 | H6: 1エリア合計目安 | I6: 補足
A7: 悪夢構成 | B7: 汎用2+特殊1 | C7: 汎用1-2+特殊2-3 | D7: 汎用1-2+特殊3-4 | E7: 強敵1+汎用2+特殊1 | F7: 強敵1+汎用1+特殊2 | G7: 強敵1+特殊2-3 | H7: 汎用4-6種 / 特殊4-5種 / 強敵3種 | I7: 全ステージ完全新規ではなく、組合せと数値で変化させる
A8: 夢の種構成 | B8: 汎用4+特殊1 | C8: 汎用4+特殊1-2 | D8: 汎用4+特殊1-3+高レア | E8: 汎用4+特殊1-2+高レア | F8: 汎用4+特殊1-2+高レア | G8: 汎用4+特殊1-3+高レア | H8: 汎用4種固定 / エリア特殊は最大6種目標 | I8: 通常枠は1000シリーズのみ。特殊夢の種IDはエリア間で重複させない
A10: 良スコア悪夢スキル参照表（採用優先候補）
A11: ID | B11: 名前 | C11: 評価 | D11: 区分 | E11: メイン効果 | O11: 採用メモ
A12: 1 | B12: 悪夢名 | C12: 4/5 | D12: 汎用 | E12: 悪夢が隣接しない隣接マス×基礎攻撃力分、攻撃力が増加する | O12: 孤立/隣接管理の導入に向く
A13: 2 | B13: 悪夢名 | C13: 5/5 | D13: 汎用 | E13: 隣接する悪夢に受けた消化ダメージ50%を分配する | O13: 隣接ダメージ分配。胃袋配置パズルと相性が強い
A14: 3 | B14: 悪夢名 | C14: 4/5 | D14: 汎用 | E14: 非隣接マス数×10%分、受ける消化ダメージを軽減する（最大100%） | O14: 軽減上限を60〜70%程度に抑えると良い
A15: 4 | B15: 悪夢名 | C15: 5/5 | D15: 汎用 | E15: 消化ライン上で占有しているマス数×基礎攻撃力50%分、攻撃力が減少する。 消化ライン下で占有しているマス数×基礎攻撃力50%分、攻撃力が増加する。 | O15: 消化ラインとの接触数を判断に変える
A16: 5 | B16: 悪夢名 | C16: 4/5 | D16: 汎用/時間 | E16: 1時以降、胃の中に存在する悪夢が受ける消化ダメージが30%減少する。 1時以降、1時間ごとに上記効果は5%ずつ増加する。 | O16: 1時以降の時間圧。上限設定推奨
A17: 6 | B17: 悪夢名 | C17: 4/5 | D17: 特殊/時間 | E17: 胃袋内で1時間存在するごとに時刻が30分経過する。 | O17: 追加時間経過。高難度・時間エリア向き
A18: 8 | B18: 悪夢名 | C18: 5/5 | D18: 特殊/寄生 | E18: 消化時、自身が占有していたすべてのマスに通常寄生型悪夢を生成する。（通常寄生型悪夢は宿主のHP50%とATK50%を保有する） | O18: 寄生生成の中核。ゴンサルなどで有効
A19: 9 | B19: 悪夢名 | C19: 5/5 | D19: 汎用/順番 | E19: 自身以外が消化時、最大HPが10%減少し、同時に攻撃力が基礎攻撃力50%分増加する。 | O19: 消化順の圧がわかりやすい
A20: 10 | B20: 悪夢名 | C20: 4/5 | D20: 高難度/順番 | E20: 自身が偶数番目に消化されなかった場合、攻撃力×300%のダメージを与える。（同時消化の場合は余剰ダメ量＞設置順で消化順が決定される） | O20: 偶数番目条件。後半・試験向き
A21: 11 | B21: 悪夢名 | C21: 4/5 | D21: 高難度/順番 | E21: 自身が奇数番目に消化されなかった場合、HP50%回復して復活する。回復量はこの効果で復活するたびに10%減少する。（同時消化の場合は余剰ダメ量＞設置順で消化順が決定される） | O21: 奇数番目復活。後半・強敵向き
A22: 12 | B22: 悪夢名 | C22: 5/5 | D22: 汎用/同時消化 | E22: 他の存在と同時刻に消化されなかったとき、低級寄生型悪夢が１体生成される。（低級寄生型悪夢は宿主のHP30%とATK0%を保有する） | O22: 同時消化を促す。軽めの寄生で使いやすい
A23: 20021 | B23: 強敵 エラミア区 001 | C23: 4/5 | D23: 強敵/エラミア | E23: 偶数時になった時に受けた消化ダメージを自身の攻撃力に変換する | O23: 偶数時の被ダメ攻撃変換。行動計画が生まれる
... A41: 20113 | B41: 強敵 イリユ洞窟 003 | C41: 4/5 | D41: 強敵/イリユ | E41: 消化ダメージを受けた時、受けた攻撃量の10%を自身の攻撃力を上昇する | O41: 被ダメ攻撃変換。配置と火力調整が必要になる
A44: 良スコア夢の種スキル参照表（採用優先候補）
A45: ID | B45: 名前 | C45: 評価 | D45: 特殊使用回数 | E45: 区分 | F45: メイン効果 | O45: サブ効果 / 採用メモ
A46: 1001 | B46: キンセンカ | C46: 5/5 | D46: 0 | E46: 汎用火力 | F46: 消化ダメージ+10% | O46: サブ：この花を消化すると消化ダメージ+20% メモ：全エリア汎用の夢の種。通常枠1000シリーズとして使用
A47: 1002 | B47: カモミール | C47: 5/5 | D47: 0 | E47: 汎用回復 | F47: ステージクリア時HP10%回復 | O47: サブ：この花を消化するとHP5%回復 メモ：全エリア汎用の夢の種。通常枠1000シリーズとして使用
A48: 1003 | B48: トケイソウ | C48: 5/5 | D48: 0 | E48: 汎用速度 | F48: 消化間隔-5%。この花はひとつしか持てない | O48: サブ：この花を消化すると消化間隔-15% メモ：全エリア汎用の夢の種。通常枠1000シリーズとして使用
A49: 1004 | B49: アネモネ | C49: 4/5 | D49: 0 | E49: 汎用蘇生補助 | F49: 蘇生時の回復量がHP上限+50%増加。 | O49: サブ：この花を消化すると蘇生時の時間経過が発生しない。 メモ：全エリア汎用の夢の種。通常枠1000シリーズとして使用
A50: 2002 | B50: ホウセンカ | C50: 5/5 | D50: 1 | E50: 特殊/反射 | F50: 受けるダメージ+30%。受けたダメージ30%分を次の消化ダメージに加算。 | O50: サブ：この花を消化すると消化時に受けた総合消化ダメージ100%を隣接するモノに分配して与える。 メモ：割当：エラミア区。被ダメ→攻撃変換と最も噛み合う
A51: 2003 | B51: ゲッカビジン | C51: 5/5 | D51: 1 | E51: 特殊/早期クリア | F51: 1時までにステージをクリアすると消化ダメージが永久に5%上昇する。（重複不可） | O51: サブ：この花を消化すると時間経過が通常の50%遅くなる。 メモ：割当：コロッタ街。時間成長に対して早期決着のビルド軸になる
A52: 2004 | B52: ヨルガオ | C52: 4/5 | D52: 1 | E52: 特殊/遅延クリア | F52: クリア時にHPを回復出来なくなる。4時以降にクリア時夢の種を追加で1回獲得できる。 | O52: サブ：消化時。時刻が4時以降のとき消化ダメージが200%上昇する。 メモ：割当：フェリス庭区。時刻反応・快楽消費のリスク報酬に合う
A53: 2005 | B53: フジ | C53: 5/5 | D53: 1 | E53: 特殊/消化バフ増幅 | F53: 消化ダメージ量+10%。消化中の消化ダメージアップ効果が200%上昇する。 | O53: サブ：この花を消化すると消化時に隣接する花のHPと受ける消化ダメージを100%上昇する。 メモ：割当：ルノヴァ旧市街。変則・混沌のビルド核として採用
A54: 2107 | B54: モウセンゴケ | C54: 4/5 | D54: 1 | E54: 特殊/少数配置火力 | F54: 消化ダメージを受けた悪夢に追加で20%の消化ダメージを与える | O54: サブ：胃の中に存在するモノが3体以下の場合消化ダメージ+50% メモ：割当：イリユ洞窟。少数配置・夢の種接触の導入に向く
A55: 2108 | B55: ベラドンナ | C55: 5/5 | D55: 1 | E55: 特殊/追加消化・隣接 | F55: 消化ダメージを与えたとき5%の確率で消化ダメージ200%を追加で与える。 | O55: サブ：隣接した悪夢の受ける消化ダメージを100%上昇させる。 メモ：割当：ネリクス魔法学校。比較・嫉妬・隣接弱点化に合う
A56: 2110 | B56: マツヨイグサ | C56: 4/5 | D56: 1 | E56: 特殊/消化間隔参照 | F56: 消化間隔10分ごとに消化ダメージ+2% | O56: サブ：この花を消化すると消化ラインに触れたモノに消化間隔(分)×消化ダメージの消化ダメージを配分して与える。 メモ：割当：エルメナ大学。締切・消化間隔・ライン滞在を報酬側で扱う
A57: 2113 | B57: ハス | C57: 5/5 | D57: 1 | E57: 特殊/ライン拡張 | F57: 消化ダメージ-20%。消化ライン+1 | O57: サブ：この花を消化すると消化ライン-1 メモ：割当：ルノヴァ旧市街。メリット/デメリットの反転が混沌枠に合う
... A71: 2138 | B71: ドクダミ | C71: 4/5 | D71: 1 | E71: 特殊/吐き戻し攻撃化 | F71: 吐き戻した悪夢に消化ダメージ33%を与える。吐き戻し時のダメージがHP50%になる。 | O71: サブ：この花を消化するとドラッグ操作での吐き戻しが出来なくなる。代わりに消化ダメージ+100% メモ：割当：ミルネ街。破壊・暴走を吐き戻し攻撃として表現できる
A74: 各エリア×各ステージ データ設計表（入力用）
A75: AreaID | B75: エリア | C75: 難度 | D75: ステージ | E75: 種別 | F75: 役割 | G75: メイン方向性 | H75: サブ方向性 | I75: 汎用悪夢数 | J75: 特殊悪夢数 | K75: 強敵数 | L75: 汎用種数 | M75: 特殊種数 | N75: 高レア数 | O75: 推奨悪夢候補ID | R75: 推奨夢の種候補ID | U75: 設計メモ
A76: 1. ルノヴァ旧市街｜★4混沌｜方向性：変則・混沌 / 順番/寄生/時間の混合｜強敵候補：20021/20051/20093等を変則流用｜特殊種候補：2005,2113
A77: 1 | B77: ルノヴァ旧市街 | C77: ★4混沌 | D77: 通常1 | E77: 通常 | F77: 導入A | G77: 変則・混沌 | H77: 順番/寄生/時間の混合 | I77: 2 | J77: 1 | K77: 0 | L77: 4 | M77: 1 | N77: 0 | O77: 汎用:10,11,12,7 | R77: 汎用:1001,1002,1003,1004 / 特殊:2005,2113 | U77: 汎用2+特殊1。メイン方向性を1つだけ見せる 悪夢: 汎用2+特殊1+強敵0 / 種: 汎用4+特殊1+高レア0
...

Sheet ノベルいるやつ
A1: イリユ洞窟 | C1: 1 | E1: 2 | G1: 3 | I1: end
A2: ルノヴァ旧市街 | C2: 1 | E2: 2 | G2: 3 | I2: end
A3: エルメナ大学 | C3: 1 | E3: 2 | G3: 3 | I3: end
A4: 大樹リラン駐屯地 | C4: 1 | E4: 2 | G4: 3 | I4: end
A5: ending | C5: 普通にクリア | E5: ダメダメクリア | G5: 旧市街クリア
A6: ラーラ | C6: 勝敗判定・負け１ | E6: 勝敗判定・勝ち１ | G6: 勝敗判定・同点１
C7: 勝敗判定・負け２ | E7: 勝敗判定・勝ち２ | G7: 勝敗判定・同点２
C8: 勝敗判定・負け３ | E8: 勝敗判定・勝ち３ | G8: 勝敗判定・同点３
C9: 訪問先・ミルネ街 | E9: 訪問先・エラミア区 | G9: 訪問先・ザイカ行政区 | I9: 訪問先・ゴンザル地区
C10: 訪問先・ネリクス魔法学校 | E10: 訪問先・フェリス庭区 | G10: 訪問先・コロッタ街
C11: 通常接触・１ | E11: 通常接触・２ | G11: 通常接触・３ | I11: 通常接触・４
C12: 通常接触・５ | E12: 通常接触・６ | G12: 通常接触・７ | I12: 通常接触・８
C13: 通常接触失敗・１
